<?xml version="1.0" ?>

<robot name="my_model" xmlns:xacro="http://www.ros.org/wiki/xacro">
  <!-- Wheels -->
  <!-- in kg-->
  <!-- Defining the colors used in this robot -->
  
  <material name="Black">
    <color rgba="0.0 0.0 0.0 1.0"/>
  </material>
  <material name="Red">
    <color rgba="0.8 0.0 0.0 1.0"/>
  </material>
  <material name="Green">
    <color rgba="0.0 0.8 0.0 1.0"/>
  </material>
  <material name="White">
    <color rgba="1.0 1.0 1.0 1.0"/>
  </material>
  <material name="Blue">
    <color rgba="0.0 0.0 0.8 1.0"/>
  </material>
   --&gt; 

  <!-- BASE-LINK -->
  <!--Actual body/chassis of the robot-->

  <link name="base_link">
    <inertial>
      <mass value="0.1"/>
      <origin xyz="0 0 0.05"/>
      <!--The 3x3 rotational inertia matrix. -->
       <inertia ixx="0.0000282916666667" ixy="0" ixz="0" iyy="0.0000282916666667" iyz="0" izz="0.00005625"/>
    </inertial>
    <visual>
      <origin rpy="0 0 0" xyz="0 0 0"/>
      <geometry>
        <cylinder length="0.004" radius="0.08"/>
      </geometry>
      <material name="White"/>
    </visual>
    <collision>
      <origin rpy="0 0 0 " xyz="0 0 0"/>
      <geometry>
        <cylinder length="0.005" radius="0.08"/>
      </geometry>
    </collision>
  </link>
  <gazebo reference="base_link">
    <material>Gazebo/White</material>
    <turnGravityOff>false</turnGravityOff>
  </gazebo>

  <!-- BASE-upperlink -->

<!-- <link name="base_upperlink">
    <inertial>
      <mass value="0.01"/>
      <origin xyz="0 0 0"/>
      <inertia ixx="0.0001" ixy="0" ixz="0" iyy="0.0001" iyz="0" izz="0.0001"/>
    </inertial>
    <visual>
      <origin rpy="0 0 0" xyz="0 0 0"/>
      <geometry>
        <cylinder length="0.004" radius="0.12"/>
      </geometry>
  <material name="White"/>  
  </visual>
    <collision>
      <origin rpy="0 0 0 " xyz="0 0 0"/>
      <geometry>
        <cylinder length="0.005" radius="0.08"/>
      </geometry>
   <material name="White"/>
    </collision>
  </link>
  <gazebo reference="base_upperlink">
  
    <turnGravityOff>false</turnGravityOff>
  </gazebo>
  <joint name="base_upperlink_joint" type="fixed">
    <origin rpy="0 0 0" xyz="0 0 0.054"/>
    <parent link="base_link"/>
    <child link="base_upperlink"/>
  </joint>
 -->



  <!--fb : front, back ; lr: left, right -->
  <link name="right_wheel">
    <visual>
      <origin rpy="1.57079632679 0  0 " xyz="0 0 0"/>
      <geometry>
        <cylinder length="0.02" radius="0.0325"/>
      </geometry>
      <material name="Green"/>
    </visual>
    <collision>
      <origin rpy="1.57079632679 0 0 " xyz="0 0 0"/>
      <geometry>
        <cylinder length="0.005" radius="0.025"/>
      </geometry>
    </collision>
    <inertial>
      <mass value="0.5"/>
      <origin xyz="0 0 0"/>
      <inertia ixx="0.0001" ixy="0" ixz="0" iyy="0.0001" iyz="0" izz="0.0001"/>
    </inertial>
  </link>
  <gazebo reference="right_wheel">
    <mu1 value="1.0"/>
    <mu2 value="1.0"/>
    <kp value="100000.0"/>
    <kd value="1.0"/>
    <fdir1 value="1 0 0"/>
    <material>Gazebo/Green</material>
    <turnGravityOff>false</turnGravityOff>
  </gazebo>
  <joint name="right_wheel_joint" type="continuous">
    <parent link="base_link"/>
    <child link="right_wheel"/>
      <origin rpy="0 0 0" xyz="-0.03 0.09 0"/>
    <axis rpy="0 0 0" xyz="0 1 0"/>
    <limit effort="100" velocity="100"/>
    <joint_properties damping="0.0" friction="0.0"/>
  </joint>
  <!-- Transmission is important to link the joints and the controller -->


  <transmission name="right_wheel_joint_trans">
    <type>transmission_interface/SimpleTransmission</type>
    <joint name="right_wheel_joint"/>
    <actuator name="right_wheel_joint_motor">
      <hardwareInterface>EffortJointInterface</hardwareInterface>
      <mechanicalReduction>1</mechanicalReduction>
    </actuator>
  </transmission>
  
  <!--left motor -->
  <link name="left_wheel">
    <visual>
      <origin rpy="1.57079632679 0  0 " xyz="0 0 0"/>
      <geometry>
        <cylinder length="0.02" radius="0.0325"/>
      </geometry>
      <material name="Green"/>
    </visual>
    <collision>
      <origin rpy="1.57079632679 0 0 " xyz="0 0 0"/>
      <geometry>
        <cylinder length="0.005" radius="0.025"/>
      </geometry>
    </collision>
    <inertial>
      <mass value="0.5"/>
      <origin xyz="0 0 0"/>
      <inertia ixx="0.0001" ixy="0" ixz="0" iyy="0.0001" iyz="0" izz="0.0001"/>
    </inertial>
  </link>
  <gazebo reference="left_wheel">
    <mu1 value="1.0"/>
    <mu2 value="1.0"/>
    <kp value="100000.0"/>
    <kd value="1.0"/>
    <fdir1 value="1 0 0"/>
    <material>Gazebo/Green</material>
    <turnGravityOff>false</turnGravityOff>
  </gazebo>
  <joint name="left_wheel_joint" type="continuous">
    <parent link="base_link"/>
    <child link="left_wheel"/>
    <origin rpy="0 0 0" xyz="-0.03 -0.09 0"/>
    <axis rpy="0  0" xyz="0 1 0"/>
    <limit effort="100" velocity="100"/>
    <joint_properties damping="0.0" friction="0.0"/>
  </joint>

  <!-- Transmission is important to link the joints and the controller -->
  <transmission name="left_wheel_joint_trans">
    <type>transmission_interface/SimpleTransmission</type>
    <joint name="left_wheel_joint"/>
    <actuator name="left_wheel_joint_motor">
      <hardwareInterface>EffortJointInterface</hardwareInterface>
      <mechanicalReduction>1</mechanicalReduction>
    </actuator>
  </transmission>

  <!--Caster front  -->

  <link name="caster_front_link">
    <visual>
      <origin rpy="1.57079632679 0 0" xyz="0 0 0"/>
      <geometry>
        <sphere radius="0.01214"/>
      </geometry>
      <material name="Green"/>
    </visual>
    <collision>
      <geometry>
        <sphere radius="0.007"/>
      </geometry>
      <origin rpy="1.57079632679 0 0" xyz="0 0 0"/>
    </collision>
    <inertial>
      <mass value="0.5"/>
      <origin xyz="0 0 0"/>
      <inertia ixx="0.0000001" ixy="0.0" ixz="0.0" iyy="0.0000001" iyz="0.0" izz="0.0000001"/>
    </inertial>
  </link>
  <joint name="caster_front_joint" type="continuous">
    <parent link="caster_link"/>
    <child link="caster_front_link"/>
    <origin rpy="0 0 0" xyz="0.05 0 -0.01545"/>
    <axis rpy="0 0 0" xyz="0 1 0"/>
  </joint>
  <gazebo reference="caster_front_link">
<!--     <mu1 value="1.0"/>
    <mu2 value="1.0"/>
    <kp value="100000.0"/>
    <kd value="1.0"/>
    <fdir1 value="1 1 0"/> -->
    <turnGravityOff>false</turnGravityOff>
    <material>Gazebo/Green</material>
  </gazebo>
  
<link name="caster_link">
    <visual>
      <origin rpy="0 0  0 " xyz="0.05 0 0"/>
      <geometry>
        <cylinder length="0.02586" radius="0.01214"/>
      </geometry>
      <material name="Green"/>
    </visual>
    <collision>
      <origin rpy="0 0 0 " xyz="0.05 0 0"/>
      <geometry>
        <cylinder length="0.02586" radius="0.005"/>
      </geometry>
    </collision>
    <inertial>
      <mass value="0.05"/>
      <origin xyz="0.05 0 0"/>
      <inertia ixx="0.00001" ixy="0" ixz="0" iyy="0.00001" iyz="0" izz="0.00001"/>
    </inertial>
  </link>
  
<joint name="caster_front_joint_base" type="fixed">
    <parent link="base_link"/>
    <child link="caster_link"/>
    <origin rpy="0 0 0" xyz="0 0.0 -0.00545"/>
  </joint>
  <gazebo reference="caster_link">
    <turnGravityOff>false</turnGravityOff>
    <material>Gazebo/Green</material>
  </gazebo>
  
  



  <!-- hokuyo -->
<joint name="laser_sensor" type="fixed">
    <axis xyz="1 0 0"/>      
    <origin rpy="0 .02 0" xyz="0.05 0 0.015"/>
    <parent link="base_link"/>
    <child link="laser_link"/>
  </joint>

<link name="laser_link">
  <inertial>
    <mass value="0.001"/>
    <origin rpy="0 0 0" xyz="0.05 0 0"/>
    <inertia ixx="0.001" ixy="0" ixz="0" iyy="0.001" iyz="0" izz="0.001"/>
  </inertial>
  <visual>
    <origin rpy="0 0 0" xyz="0 0 0"/>
    <geometry>
      <box size="0.03 0.03 0.03"/>
    </geometry>
    <material name="Red"/>  
  </visual>
  <collision>
    <origin rpy="0 0 0" xyz="0 0 0"/>
    <geometry>
      <box size=".03 .03 .03"/>
    </geometry>
  </collision>
</link>

  <gazebo reference="laser_link">
   <material>Gazebo/Red</material>
    <turnGravityOff>false</turnGravityOff>
   
 <sensor name="laser_sensor" type="ray">
   
   <pose>0 0 0 0 0 0 0</pose>
      <visualize>true</visualize>
      <update_rate>100</update_rate>
      <ray>
  
      <scan>
          <horizontal>
            <samples>700</samples>
            <resolution>1</resolution>
            <min_angle>-1.57079632679</min_angle>
            <max_angle>1.57079632679</max_angle>
          </horizontal>
        </scan>

        <range>
          <min>0.1</min>
          <max>30</max>
          <resolution>0.001</resolution>
        </range>

      </ray>

      <plugin filename="libgazebo_ros_laser.so" name="gazebo_ros_head_hokuyo_controller">
        <topicName>/scan</topicName>
        <frameName>base_link</frameName>
      </plugin>
   </sensor>
  </gazebo>


<!--   <link name="support_1">
    <visual>
      <origin rpy="0 0 0" xyz="0 0 0"/>
      <geometry>
       <cylinder length="0.05" radius="0.01"/>
      </geometry>
   <material name="Black"/>
    </visual>

  </link> 

  <joint name="support_joint1" type="fixed">
    <origin rpy="0 0 0" xyz="0.04 -0.07 0.027"/>
    <parent link="base_link"/>
    <child link="support_1"/>
  </joint>
  
  <gazebo reference="support_1">
    <turnGravityOff>false</turnGravityOff>
    <material>Gazebo/Black</material>
  </gazebo>

<link name="support_2">
    <visual>
      <origin rpy="0 0 0" xyz="0 0 0"/>
      <geometry>
       <cylinder length="0.05" radius="0.01"/>
      </geometry>
   <material name="Black"/>
    </visual>

  </link> 

  <joint name="support_joint2" type="fixed">
    <origin rpy="0 0 0" xyz="0.04 0.07 0.027"/>
    <parent link="base_link"/>
    <child link="support_2"/>
  </joint>
  <gazebo reference="support_2">
    <turnGravityOff>false</turnGravityOff>
    <material>Gazebo/Black</material>
  </gazebo>

<link name="support_3">
    <visual>
      <origin rpy="0 0 0" xyz="0 0 0"/>
      <geometry>
       <cylinder length="0.05" radius="0.01"/>
      </geometry>
   <material name="Black"/>
    </visual>

  </link> 

  <joint name="support_joint3" type="fixed">
    <origin rpy="0 0 0" xyz="-0.06 -0.07 0.027"/>
    <parent link="base_link"/>
    <child link="support_3"/>
  </joint>

  <gazebo reference="support_3">
    <turnGravityOff>false</turnGravityOff>
    <material>Gazebo/Black</material>
  </gazebo>

<link name="support_4">
    <visual>
      <origin rpy="0 0 0" xyz="0 0 0"/>
      <geometry>
       <cylinder length="0.05" radius="0.01"/>
      </geometry>
   <material name="Black"/>
    </visual>

  </link> 

  <joint name="support_joint4" type="fixed">
    <origin rpy="0 0 0" xyz="-0.06 0.07 0.027"/>
    <parent link="base_link"/>
    <child link="support_4"/>
  </joint>

  <gazebo reference="support_4">
    <turnGravityOff>false</turnGravityOff>
    <material>Gazebo/Black</material>
  </gazebo> -->

<gazebo>
    <plugin filename="libgazebo_ros_diff_drive.so" name="differential_drive_controller_front">
      <rosDebugLevel>Debug</rosDebugLevel>
      <publishWheelTF>True</publishWheelTF>
      <publishTf>1</publishTf>
      <publishWheelJointState>true</publishWheelJointState>
      <alwaysOn>true</alwaysOn>
      <updateRate>100.0</updateRate>
      <leftJoint>left_wheel_joint</leftJoint>
      <rightJoint>right_wheel_joint</rightJoint>
      <wheelSeparation>0.3</wheelSeparation>
      <wheelDiameter>0.065</wheelDiameter>
      <broadcastTF>1</broadcastTF>
      <wheelTorque>30</wheelTorque>
      <wheelAcceleration>1.8</wheelAcceleration>
      <commandTopic>cmd_vel</commandTopic>
      <odometryFrame>odom</odometryFrame>
      <odometryTopic>odom</odometryTopic>
      <robotBaseFrame>base_link</robotBaseFrame>
    </plugin>
  </gazebo>
 
</robot>
